Workbook

Sheet Executive_Summary
A1: IHSG STORM (ihsg.badai.tech) — FREEMIUM FINANCIAL MODEL & UNIT ECONOMICS V3.1 (ONE-TIME PASS)
A2: Model Sekali Bayar (One-Time Pass), Jalur Upgrade, Akun Pemasaran (Comp), Treadmill Akuisisi & Rekonsiliasi Kas (Revisi v3.1: Drop Supabase Pro & Konfirmasi Jim D8) | Oscar
A4: 1. KEPUTUSAN FINAL & STRUKTUR HARGA ONE-TIME PASS V3 (KEPUTUSAN BOBBY & REKOMENDASI OSCAR/JIM) [S]
A5: Nama Paket / Pass | B5: Segmen Sasaran | C5: Pass 1-Bulan (30 Hari) [S] | D5: Pass 12-Bulan (365 Hari) [S] | E5: Diskon 12M [S] | F5: Fitur Utama [S] | G5: Aturan Pembayaran & Batasan [S]
A6: Gratis (Pemula) | B6: Investor kasual & leads top-of-funnel | C6: 0 | D6: 0 | E6: - | F6: Snapshot KSEI terbaru, pencarian emiten & investor >1%, top 10 pemegang | G6: Akses permanen gratis; tanpa histori diff, tanpa alert, tanpa ekspor CSV
A7: Investor (Ritel) | B7: Investor ritel santai (cek bulanan saat KSEI rilis) | C7: 19000 | D7: 190000 | E7: 0.1667 | F7: Diff kepemilikan 1 bulan terbaru, 20+ grup konglomerasi, watchlist 10 saham, digest email | G7: Sekali bayar via QRIS (tanpa auto-renew). Habis 30/365 hari kembali ke Gratis
A8: Pakar / Trader (Pro) | B8: Trader aktif, swing trader & analis institusi | C8: 49000 | D8: 490000 | E8: 0.1667 | F8: Semua fitur Investor + histori multi-bulan lengkap, Bot Telegram alert instan, watchlist 50 saham, 50 CSV/bln | G8: Sekali bayar via QRIS/VA (tanpa auto-renew). Fitur profesional penuh tanpa kompromi
A9: Founder Pass (Lifetime) | B9: Early supporter / pendukung modal awal | C9: - | D9: 599000 | E9: - | F9: Akses Pakar seumur hidup, badge eksklusif 'Founder', kuota strictly capped 50 kursi | G9: Hanya 50 kursi (Rp 29,95M kas awal). Menolak keras LTD publik Rp19k/49k (Bunuh Diri)
A11: 2. RINGKASAN JALUR UPGRADE & MARKETING COMP ACCOUNTS V3 [S/A]
A12: Dimensi Fitur | B12: Kebijakan / Aturan | C12: Harga / Biaya | D12: Dampak Pendapatan / Kas | E12: Perlakuan Trigger VPS Fase 0 | F12: Target Break-Even ROI | G12: Rasional & Kepatuhan Risiko
A13: Upgrade Pass 1-Bulan (<= 7 Hari) | B13: Bayar selisih penuh; masa aktif di-reset 30 hari penuh Pakar | C13: 30000 | D13: Tambahan kas Rp 30.000 / transaksi | E13: Dihitung sebagai paying upgrade | F13: Konversi instan | G13: Mendorong konversi cepat sebelum minggu pertama berakhir
A14: Upgrade Pass 12-Bulan (Tahunan) | B14: Prorata sisa bulan penuh: Rp 25.000 x sisa bulan | C14: 225000 | D14: Rata-rata tambahan kas Rp 225k | E14: Dihitung sebagai paying upgrade | F14: ARPU expansion | G14: Menjaga masa aktif tetap sinkron dengan tanggal akhir tahunan
A15: Loyalty Renewal Discount | B15: Potongan harga jika beli pass baru <= 7 hari pasca-kedaluwarsa | C15: Rp 5.000 / 10% | D15: Mengurangi churn manual pasca-habis | E15: Pengguna berulang (repeat buyer) | F15: Menaikkan retensi 15-20% | G15: Mengompensasi tiadanya auto-debit dengan insentif ekonomi
A16: Marketing Comp Accounts (5 Akun) | B16: 5 akun Pakar gratis untuk influencer, admin grup & early tester | C16: Rp 0 kas masuk (Hibah) | D16: Forgone revenue: Rp 245.000 / bln | E16: TIDAK DIHITUNG (Strict Excluded) | F16: Butuh 5 Pakar / 14 Inv | G16: Admin grant via CLI ihsg.admin comp grant; Strictly Excluded dari paying trigger (<5)
A18: 3. MATRIKS PERBANDINGAN EMPAT SKENARIO FINANSIAL TAHUN KE-1 (V3 ONE-TIME PASS) [S/A]
A19: Dimensi Kinerja Finansial (12 Bulan) | B19: Tipe | C19: Skenario 1: Pesimis (Cold-Start) | D19: Skenario 2: Konservatif | E19: Skenario 3: Moderat (Base) | F19: Skenario 4: Optimis | G19: Evaluasi Finansial & Realitas Kas
A20: Trafik Puncak M12 (Pengunjung) [A] | B20: [A] | C20: =Skenario_Cold_Start!M6 | D20: =Skenario_Konservatif!M6 | E20: =Skenario_Moderat_Base!M6 | F20: =Skenario_Optimis!M6 | G20: Asumsi lalu lintas unik bulanan
A21: Akumulasi Basis Akun Gratis (M12) [A] | B21: [A] | C21: =Skenario_Cold_Start!N8 | D21: =Skenario_Konservatif!N8 | E21: =Skenario_Moderat_Base!N8 | F21: =Skenario_Optimis!N8 | G21: Basis database calon pembeli (leads)
A22: Tingkat Konversi Akun Baru (%) [A] | B22: [A] | C22: =Skenario_Cold_Start!B10 | D22: =Skenario_Konservatif!B10 | E22: =Skenario_Moderat_Base!B10 | F22: =Skenario_Optimis!B10 | G22: Konversi pendaftar baru menjadi pembeli pass
A23: Tingkat Perpanjangan Manual (Repeat %) [A] | B23: [A] | C23: =Skenario_Cold_Start!B17 | D23: =Skenario_Konservatif!B17 | E23: =Skenario_Moderat_Base!B17 | F23: =Skenario_Optimis!B17 | G23: Persentase pembeli 1M yang membeli pass baru setelah habis
A24: Pengguna Aktif Berbayar Kas M12 [A] | B24: [A] | C24: =Skenario_Cold_Start!M31 | D24: =Skenario_Konservatif!M31 | E24: =Skenario_Moderat_Base!M31 | F24: =Skenario_Optimis!M31 | G24: Pengguna dengan pass valid aktif pada akhir M12
A25: Akun Promosi Pemasaran (Comp) M12 [S] | B25: [S] | C25: 5 | D25: 5 | E25: 5 | F25: 5 | G25: 5 akun Pakar gratis (Strictly exclude dari paying trigger)
A26: Total Kas Masuk Bruto (12 Bulan) [A] | B26: [A] | C26: =Skenario_Cold_Start!N41 | D26: =Skenario_Konservatif!N41 | E26: =Skenario_Moderat_Base!N41 | F26: =Skenario_Optimis!N41 | G26: Total uang tunai masuk dari penjualan pass & upgrade
A27: Biaya Payment Gateway & Refund (12M) [S/A] | B27: [S/A] | C27: =Skenario_Cold_Start!N46 | D27: =Skenario_Konservatif!N46 | E27: =Skenario_Moderat_Base!N46 | F27: =Skenario_Optimis!N46 | G27: MDR QRIS ~1,8% + Cadangan refund 1% + Settlement Rp20k/bln
A28: Beban Operasional Tetap (OpEx 12M) [S/A] | B28: [S/A] | C28: =Skenario_Cold_Start!N55 | D28: =Skenario_Konservatif!N55 | E28: =Skenario_Moderat_Base!N55 | F28: =Skenario_Optimis!N55 | G28: Phase 0 VPS + AI Claude $20 + EODHD + Marketing (SQLite/Litestream Rp 0; Supabase Pro didrop per Jim D3)
A29: LABA OPERASIONAL KAS (EBITDA 12M) [A] | B29: [A] | C29: =Skenario_Cold_Start!N57 | D29: =Skenario_Konservatif!N57 | E29: =Skenario_Moderat_Base!N57 | F29: =Skenario_Optimis!N57 | G29: Arus kas operasional bersih entitas
A30: Margin Laba Kas EBITDA (%) [A] | B30: [A] | C30: =Skenario_Cold_Start!N58 | D30: =Skenario_Konservatif!N58 | E30: =Skenario_Moderat_Base!N58 | F30: =Skenario_Optimis!N58 | G30: Rasio EBITDA terhadap penerimaan kas bruto
A31: Pajak PPh Final UMKM PP 55/2022 (WPOP) [S] | B31: [S] | C31: =Skenario_Cold_Start!N59 | D31: =Skenario_Konservatif!N59 | E31: =Skenario_Moderat_Base!N59 | F31: =Skenario_Optimis!N59 | G31: WPOP bebas pajak s.d. omzet Rp 500M (Pasal 69 PP 55/2022)
A32: LABA BERSIH KAS SETELAH PAJAK [A] | B32: [A] | C32: =Skenario_Cold_Start!N60 | D32: =Skenario_Konservatif!N60 | E32: =Skenario_Moderat_Base!N60 | F32: =Skenario_Optimis!N60 | G32: Laba kas bersih setelah kewajiban pajak
A33: Margin Kas Bersih Setelah Pajak (%) [A] | B33: [A] | C33: =Skenario_Cold_Start!N61 | D33: =Skenario_Konservatif!N61 | E33: =Skenario_Moderat_Base!N61 | F33: =Skenario_Optimis!N61 | G33: Margin laba bersih kas akhir
A34: Bulan Titik Impas Operasional (EBITDA > 0) | B34: [A] | C34: Tidak Pernah (Defisit) | D34: Bulan ke-4 | E34: Bulan ke-2 | F34: Bulan ke-1 | G34: Bulan pertama arus kas bulanan melampaui pengeluaran
A35: Bulan Titik Impas Kas Akumulatif | B35: [A] | C35: Tidak Pernah (Defisit) | D35: Bulan ke-6 | E35: Bulan ke-2 | F35: Bulan ke-1 | G35: Bulan saldo kas kumulatif berbalik menjadi positif
A36: SALDO KAS AKHIR TAHUN KE-1 [A] | B36: [A] | C36: =Skenario_Cold_Start!M62 | D36: =Skenario_Konservatif!M62 | E36: =Skenario_Moderat_Base!M62 | F36: =Skenario_Optimis!M62 | G36: Uang kas cair yang mengendap di bank pada akhir M12
A38: 4. ANALISIS TREADMILL AKUISISI: SATU KALI BAYAR VS PENDAPATAN BERULANG (ONE-TIME VS RECURRING) [S/A]
A39: Dimensi Evaluasi | B39: Model Recurring Subscription (Auto-Renew) | C39: Model One-Time Pass (Sekali Bayar) | D39: Dampak Bisnis & Evaluasi Oscar
A40: Mekanisme Pembayaran | B40: Auto-debit kartu / e-wallet per bulan otomatis | C40: Manual push QRIS per transaksi (tanpa auto-renew) | D40: QRIS tidak bisa auto-debit; model One-Time sesuai fakta rail Indonesia
A41: Retensi Bulanan / Churn | B41: Churn 6,5% / bln (Retensi otomatis 93,5%) | C41: Churn manual ~55% / bln (Repeat purchase 45%) | D41: Friksi transaksi manual menurunkan retensi bulanan secara tajam
A42: Pembeli Baru Menutup OpEx Fase 0 (Rp 390k) | B42: Hanya butuh 1-2 pembeli baru / bln (menambal churn) | C42: Wajib 15 pembeli baru / bln jika zero renewal | D42: Setiap awal bulan kas kembali ke Rp 0; wajib akuisisi konstan
A43: Pembeli Baru Menutup OpEx Fase 1 (Rp 710k) | B43: Hanya butuh 2-3 pembeli baru / bln | C43: Wajib 27 pembeli baru / bln jika zero renewal | D43: Treadmill akuisisi makin berat seiring bertambahnya beban server
A44: Annualized Run-Rate (ARR M12) | B44: Rp 322 Juta (Terkontrak berulang) | C44: Rp 0 (NOL - Tidak ada ARR terjamin) | D44: Valuasi SaaS berbasis kelipatan ARR hilang; bisnis menjadi transactional
...

Sheet Model_Parameters
A1: IHSG STORM (ihsg.badai.tech) — PARAMETER FINANSIAL & MODEL V3
A2: Selector Struktur Pembayaran, Biaya Tangga OpEx, AI Agent Squad, PPh PP 55/2022, Gateway & Comp Accounts (v3.1: Drop Supabase Pro per Jim D3) | Oscar
A4: 1. STRUKTUR PEMBAYARAN & SELECTOR UTAMA (KEPUTUSAN FINAL BOBBY & REKOMENDASI OSCAR)
A5: Parameter Struktur | B5: Nilai / Pilihan Terpilih | C5: Status / Opsi | D5: Keterangan Finansial & Arahan Founder
A6: Model Pembayaran Aktif (Switch Selector) | B6: One-Time Pass (Fixed-Term) | C6: One-Time / Recurring / Lifetime | D6: Arahan Final Bobby: ONE-TIME ONLY. Rekomendasi Oscar & Jim: Pass 1-Bulan & Pass 12-Bulan (Lifetime Rp19k/49k Ditolak Fatal)
A7: Investor: Pass 1-Bulan (30 Hari) [S] | B7: 19000 | C7: IDR / transaksi | D7: Akses 30 hari bayar sekali via QRIS (Nett Rp 18.306 setelah gateway & refund)
A8: Investor: Pass 12-Bulan (365 Hari) [S] | B8: 190000 | C8: IDR / transaksi | D8: Akses 365 hari (bayar 10 bulan dapat 12, diskon 16,7%, kas di muka Rp 190k)
A9: Pakar: Pass 1-Bulan (30 Hari) [S] | B9: 49000 | C9: IDR / transaksi | D9: Akses 30 hari bayar sekali via QRIS (Nett Rp 47.724 setelah gateway & refund)
A10: Pakar: Pass 12-Bulan (365 Hari) [S] | B10: 490000 | C10: IDR / transaksi | D10: Akses 365 hari (bayar 10 bulan dapat 12, diskon 16,7%, kas di muka Rp 490k)
A11: Founder Pass (Lifetime Pro - Capped 50 Kursi) [S/A] | B11: 599000 | C11: IDR / kursi | D11: Opsi modal awal darurat (maks 50 kursi = Rp 29,95M kas di muka; menolak LTD tanpa batas)
A12: Harga Lifetime Rp 19k / Rp 49k Status [S] | B12: DITOLAK (FATAL) | C12: Analisis Risiko | D12: Tidak dapat menutup biaya operasional berkelanjutan (Rp 390k-Rp 1,4M/bln); liabilitas abadi
A14: 2. ATURAN JALUR UPGRADE (UPGRADE PATH: INVESTOR -> PAKAR)
A15: Rasio Konversi Upgrade Investor ke Pakar (%) [A] | B15: 0.08 | C15: 8,0% Cohort | D15: Asumsi: 8% dari pembeli Investor meng-upgrade ke paket Pakar
A16: Biaya Upgrade Pass 1-Bulan (Dalam 7 Hari) [S] | B16: 30000 | C16: IDR flat | D16: Bayar selisih penuh: Rp 49.000 - Rp 19.000 = Rp 30.000. Reset 30 hari Pakar penuh!
A17: Biaya Upgrade Pass 12-Bulan (Prorata per Sisa Bulan) [A] | B17: 25000 | C17: IDR / bulan | D17: Prorata selisih tahunan: (Rp 490k - Rp 190k) / 12 = Rp 25.000/bln sisa masa aktif
A18: Perpanjangan Cepat (Loyalty Renewal Discount - 1M) [A] | B18: 5000 | C18: IDR potongan | D18: Diskon Rp 5.000 jika membeli pass baru dalam <= 7 hari setelah kedaluwarsa
A19: Perpanjangan Cepat (Loyalty Renewal Discount - 12M) [A] | B19: 0.1 | C19: 10% potongan | D19: Diskon 10% tambahan untuk perpanjangan pass 12-bulan dalam <= 7 hari
A20: Kebijakan Penurunan Paket (Downgrade) & Refund [S] | B20: NO REFUND / NO MID-TERM DOWNGRADE | C20: Kebijakan Operasional | D20: Tidak ada refund kas di tengah periode; penurunan tier berlaku otomatis saat masa aktif habis
A22: 3. KEBIJAKAN MARKETING COMP ACCOUNTS (5 AKUN PRO/PLUS GRATIS)
A23: Jumlah Kuota Akun Comp Promosi [S] | B23: 5 | C23: Akun Aktif Maks | D23: Diberikan kepada influencer saham, admin komunitas, dan tester awal terverifikasi
A24: Tier Akses yang Diberikan [S] | B24: Pakar (Pro) | C24: Fitur Tertinggi | D24: Wajib Pakar agar influencer bisa memamerkan bot Telegram alert dan histori KSEI
A25: Durasi Akses Hibah (Grant Duration) [S] | B25: 90 | C25: Hari (3 Bulan) | D25: Masa aktif 90 hari; perpanjangan 90 hari jika mempublikasikan >= 2 ulasan publik
A26: Metode Pemberian Akses [S] | B26: Admin Grant (By Email/Auth) | C26: Bypass Gateway | D26: Pemberian langsung via admin CLI ihsg.admin comp grant ke tabel entitlements (Rp 0 bypass, tanpa invoice Xendit)
A27: Beban Kas Marginal per Akun per Bulan [A] | B27: 2000 | C27: IDR / akun / bln | D27: Beban kueri database SQLite/WAL & Litestream di VPS sangat ringan (~Rp 0); Telegram Bot API gratis 100%
A28: Opportunity Cost (Forgone Revenue) per Bulan [S] | B28: 245000 | C28: IDR / bln | D28: =5 akun x Rp 49.000 = Rp 245.000 / bulan (Rp 2.940.000 / tahun)
A29: Status Penghitungan Trigger Migrasi VPS Fase 0 [S] | B29: STRICT EXCLUDED (NOL) | C29: Metrik Audit | D29: TIDAK DIHITUNG sebagai paying user; hanya transaksi kas riil > Rp 0 yang dihitung
A30: Target Konversi Impas (BE ROI) - Investor 1M [A] | B30: 14 | C30: Pembeli / bln | D30: 5 akun comp impas jika seluruh influencer menghasilkan 14 pembeli Investor baru/bln
A31: Target Konversi Impas (BE ROI) - Pakar 1M [A] | B31: 5 | C31: Pembeli / bln | D31: 5 akun comp impas jika menghasilkan hanya 5 pembeli Pakar baru/bln (1 per influencer)
A32: Target Konversi Impas (BE ROI) - Pakar 12M [A] | B32: 1 | C32: Pembeli / 2 bln | D32: 1 pembeli Pakar 12-Bulan (Rp 490k) menutup biaya promosi 5 comp accounts selama 2 bulan!
A34: 4. JADWAL TANGGA BIAYA OPERASIONAL TETAP (STEPPED OPEX SCHEDULE - IDR / BULAN) [S]
A35: Komponen Biaya Tetap / Vendor | B35: Fase 0 (<5 Subs) | C35: Fase 1 (5-49 Subs) | D35: Fase 2 (50-499 Subs) | E35: Fase 3 (500+ Subs) | F35: Keterangan & Trigger [S]
A36: Vercel Pro (Hosting Web & Edge Functions) [S] | B36: 0 | C36: 320000 | D36: 320000 | E36: 320000 | F36: Phase 0 VPS mandiri Rp 0. Wajib Vercel Pro $20 saat >= 5 paying users
A37: Alokasi Domain & DNS Routing [S] | B37: 20000 | C37: 20000 | D37: 20000 | E37: 20000 | F37: Subdomain ihsg.badai.tech + alokasi DNS
A38: Operasional VPS & Scraper KSEI [S] | B38: 50000 | C38: 50000 | D38: 50000 | E38: 50000 | F38: IDCloudHost 103.179.56.61 cron scraper KSEI harian
A39: SUB-TOTAL INFRASTRUKTUR TEKNOLOGI [S] | B39: =SUM(B36:B38) | C39: =SUM(C36:C38) | D39: =SUM(D36:D38) | E39: =SUM(E36:E38) | F39: Fase 0 super ramping (Rp 70k); Fase 1+ stabil Rp 390k/bln
A40: Biaya Operasional AI Agent Squad (Claude) [S] | B40: 320000 | C40: 320000 | D40: 320000 | E40: 320000 | F40: USD 20/bln @ Rp 16.000 flat shared subscription (Konfirmasi Bobby)
A41: Feed Data Pasar Resmi (EODHD $20) [S] | B41: 0 | C41: 0 | D41: 320000 | E41: 320000 | F41: >= 50 Subs atau M4+: Feed resmi komersial EODHD
A42: Database & Autentikasi (SQLite + Litestream / Neon Phase 1) [S] | B42: 0 | C42: 0 | D42: 0 | E42: 0 | F42: Phase 0: SQLite (WAL) + Litestream di VPS (Rp 0). Phase 1: Neon Free Tier / Dedicated VPS. Garis Supabase Pro ($25/bln) didrop total per Jim D3.
A43: TOTAL BEBAN OPERASIONAL TETAP (OPEX) [S] | B43: =B39+SUM(B40:B42) | C43: =C39+SUM(C40:C42) | D43: =D39+SUM(D40:D42) | E43: =E39+SUM(E40:E42) | F43: Fase 0: Rp 390k; Fase 1: Rp 710k; Fase 2: Rp 1,03M; Fase 3: Rp 1,03M (Supabase didrop)
A45: 5. PARAMETER PAYMENT GATEWAY (XENDIT QRIS-FIRST) & PERPAJAKAN PP 55/2022
...

Sheet Skenario_Cold_Start
A1: IHSG STORM — MODEL KEUANGAN 12 BULAN (SKENARIO 1: PESIMIS / COLD-START)
A2: Dinamika Bulanan: One-Time Pass, Perpanjangan Manual, Jalur Upgrade, Akun Comp, OpEx Phase 0 VPS (Drop Supabase) & Kas (v3.1) | Oscar
A4: Metrik / Pos Keuangan | B4: M1 (Nov) | C4: M2 (Des) | D4: M3 (Jan) | E4: M4 (Feb) | F4: M5 (Mar) | G4: M6 (Apr) | H4: M7 (Mei) | I4: M8 (Jun) | J4: M9 (Jul) | K4: M10 (Agu) | L4: M11 (Sep) | M4: M12 (Okt) | N4: Total 12 Bulan | O4: Keterangan & Formula
A5: I. TRAFIK & FUNNEL AKUISISI PENGGUNA
A6: Pengunjung Unik Bulanan [A] | B6: 400 | C6: 650 | D6: 1000 | E6: 1500 | F6: 2100 | G6: 2800 | H6: 3500 | I6: 4100 | J6: 4500 | K6: 4750 | L6: 4900 | M6: 5000 | N6: =SUM(B6:M6) | O6: Proyeksi trafik web unik bulanan
A7: Rasio Registrasi Akun Gratis (%) [A] | B7: 0.15 | C7: 0.15 | D7: 0.15 | E7: 0.15 | F7: 0.15 | G7: 0.15 | H7: 0.15 | I7: 0.15 | J7: 0.15 | K7: 0.15 | L7: 0.15 | M7: 0.15 | N7: =AVERAGE(B7:M7) | O7: Persentase pengunjung yang mendaftar gratis
A8: Pendaftaran Akun Gratis Baru (MoM) [A] | B8: =B6*B7 | C8: =C6*C7 | D8: =D6*D7 | E8: =E6*E7 | F8: =F6*F7 | G8: =G6*G7 | H8: =H6*H7 | I8: =I6*I7 | ... M8: =M6*M7 | N8: =SUM(B8:M8) | O8: Pengguna gratis baru per bulan
A9: Akumulasi Pengguna Gratis Terdaftar [A] | B9: =B8 | C9: =B9+C8 | D9: =C9+D8 | E9: =D9+E8 | F9: =E9+F8 | G9: =F9+G8 | H9: =G9+H8 | I9: =H9+I8 | J9: =I9+J8 | ... M9: =L9+M8 | N9: =M9 | O9: Total basis akun gratis kumulatif
A10: Tingkat Konversi Akun Baru ke Berbayar (%) [A] | B10: 0.01 | C10: 0.01 | D10: 0.01 | E10: 0.01 | F10: 0.01 | G10: 0.01 | H10: 0.01 | I10: 0.01 | J10: 0.01 | K10: 0.01 | L10: 0.01 | M10: 0.01 | N10: =AVERAGE(B10:M10) | O10: Persentase akun baru yang membeli pass berbayar
A11: Pelanggan Pembeli Pass Baru Total (Cohort) [A] | B11: =B8*B10 | C11: =C8*C10 | D11: =D8*D10 | E11: =E8*E10 | F11: =F8*F10 | G11: =G8*G10 | H11: =H8*H10 | I11: =I8*I10 | ... M11: =M8*M10 | N11: =SUM(B11:M11) | O11: Total pembeli baru pertama kali
A12: • Investor Pass 1-Bulan Baru (Rp 19k) [A] | B12: =B11*0.56 | C12: =C11*0.56 | D12: =D11*0.56 | E12: =E11*0.56 | F12: =F11*0.56 | G12: =G11*0.56 | H12: =H11*0.56 | I12: =I11*0.56 | ... M12: =M11*0.56 | N12: =SUM(B12:M12) | O12: 56% dari pembeli baru memilih Investor 1M
A13: • Investor Pass 12-Bulan Baru (Rp 190k) [A] | B13: =B11*0.14 | C13: =C11*0.14 | D13: =D11*0.14 | E13: =E11*0.14 | F13: =F11*0.14 | G13: =G11*0.14 | H13: =H11*0.14 | I13: =I11*0.14 | ... M13: =M11*0.14 | N13: =SUM(B13:M13) | O13: 14% dari pembeli baru memilih Investor 12M
A14: • Pakar Pass 1-Bulan Baru (Rp 49k) [A] | B14: =B11*0.24 | C14: =C11*0.24 | D14: =D11*0.24 | E14: =E11*0.24 | F14: =F11*0.24 | G14: =G11*0.24 | H14: =H11*0.24 | I14: =I11*0.24 | ... M14: =M11*0.24 | N14: =SUM(B14:M14) | O14: 24% dari pembeli baru memilih Pakar 1M
A15: • Pakar Pass 12-Bulan Baru (Rp 490k) [A] | B15: =B11*0.06 | C15: =C11*0.06 | D15: =D11*0.06 | E15: =E11*0.06 | F15: =F11*0.06 | G15: =G11*0.06 | H15: =H11*0.06 | I15: =I11*0.06 | ... M15: =M11*0.06 | N15: =SUM(B15:M15) | O15: 6% dari pembeli baru memilih Pakar 12M
A16: II. PEMBELIAN ULANG PASS 1-BULAN (REPEAT PURCHASE / MANUAL RENEWAL) [A]
A17: Tingkat Pembelian Ulang Manual (%) [A] | B17: 0.35 | C17: 0.35 | D17: 0.35 | E17: 0.35 | F17: 0.35 | G17: 0.35 | H17: 0.35 | I17: 0.35 | J17: 0.35 | K17: 0.35 | L17: 0.35 | M17: 0.35 | N17: =AVERAGE(B17:M17) | O17: Persentase pembeli 1M yang manual beli lagi saat habis
A18: Pembelian Ulang Investor Pass 1-Bulan [A] | B18: 0 | C18: =B27*C17 | D18: =C27*D17 | E18: =D27*E17 | F18: =E27*F17 | G18: =F27*G17 | H18: =G27*H17 | I18: =H27*I17 | J18: =I27*J17 | ... M18: =L27*M17 | N18: =SUM(B18:M18) | O18: Pembeli Investor 1M bulan lalu yang beli pass baru
A19: Pembelian Ulang Pakar Pass 1-Bulan [A] | B19: 0 | C19: =B29*C17 | D19: =C29*D17 | E19: =D29*E17 | F19: =E29*F17 | G19: =F29*G17 | H19: =G29*H17 | I19: =H29*I17 | J19: =I29*J17 | ... M19: =L29*M17 | N19: =SUM(B19:M19) | O19: Pembeli Pakar 1M bulan lalu yang beli pass baru
A20: III. JALUR UPGRADE TIER (INVESTOR -> PAKAR) [S/A]
A21: Tingkat Konversi Upgrade Investor ke Pakar (%) [A] | B21: 0.05 | C21: 0.05 | D21: 0.05 | E21: 0.05 | F21: 0.05 | G21: 0.05 | H21: 0.05 | I21: 0.05 | J21: 0.05 | K21: 0.05 | L21: 0.05 | M21: 0.05 | N21: =AVERAGE(B21:M21) | O21: Persentase pemegang Investor yang upgrade ke Pakar
A22: Jumlah Akun Investor 1M yang Upgrade [A] | B22: =(B12+B18)*B21 | C22: =(C12+C18)*C21 | D22: =(D12+D18)*D21 | E22: =(E12+E18)*E21 | F22: =(F12+F18)*F21 | G22: =(G12+G18)*G21 | H22: =(H12+H18)*H21 | I22: =(I12+I18)*I21 | ... M22: =(M12+M18)*M21 | N22: =SUM(B22:M22) | O22: Akun Investor 1M yang bayar selisih Rp 30k ke Pakar
A23: Pendapatan Kas Upgrade 1-Bulan (Rp 30k) [S] | B23: =B22*Model_Parameters!$B$16 | C23: =C22*Model_Parameters!$B$16 | D23: =D22*Model_Parameters!$B$16 | E23: =E22*Model_Parameters!$B$16 | F23: =F22*Model_Parameters!$B$16 | G23: =G22*Model_Parameters!$B$16 | H23: =H22*Model_Parameters!$B$16 | I23: =I22*Model_Parameters!$B$16 | ... M23: =M22*Model_Parameters!$B$16 | N23: =SUM(B23:M23) | O23: Kas masuk upgrade bulanan: Akun x Rp 30.000
A24: Pendapatan Kas Upgrade 12-Bulan (Prorata Rp 225k) [A] | B24: =(B13*(B21*0.5))*Model_Parameters!$B$17 | C24: =(C13*(C21*0.5))*Model_Parameters!$B$17 | D24: =(D13*(D21*0.5))*Model_Parameters!$B$17 | E24: =(E13*(E21*0.5))*Model_Parameters!$B$17 | F24: =(F13*(F21*0.5))*Model_Parameters!$B$17 | G24: =(G13*(G21*0.5))*Model_Parameters!$B$17 | H24: =(H13*(H21*0.5))*Model_Parameters!$B$17 | I24: =(I13*(I21*0.5))*Model_Parameters!$B$17 | ... M24: =(M13*(M21*0.5))*Model_Parameters!$B$17 | N24: =SUM(B24:M24) | O24: Kas masuk upgrade tahunan: Prorata sisa bulan
A25: TOTAL KAS MASUK DARI UPGRADE TIER [A] | B25: =B23+B24 | C25: =C23+C24 | D25: =D23+D24 | E25: =E23+E24 | F25: =F23+F24 | G25: =G23+G24 | H25: =H23+H24 | I25: =I23+I24 | ... M25: =M23+M24 | N25: =SUM(B25:M25) | O25: Total penerimaan kas dari seluruh transaksi upgrade
A26: IV. DINAMIKA PENGGUNA AKTIF BERBAYAR KAS & AKUN PROMOSI (COMP) [S/A]
A27: Pengguna Aktif Investor Pass 1-Bulan [A] | B27: =(B12+B18)-B22 | C27: =(C12+C18)-C22 | D27: =(D12+D18)-D22 | E27: =(E12+E18)-E22 | F27: =(F12+F18)-F22 | G27: =(G12+G18)-G22 | H27: =(H12+H18)-H22 | I27: =(I12+I18)-I22 | ... M27: =(M12+M18)-M22 | N27: =M27 | O27: Investor 1M aktif (dikurangi yang pindah ke Pakar)
A28: Pengguna Aktif Investor Pass 12-Bulan (Kumulatif 365 Hari) [A] | B28: =B13 | C28: =B28+C13 | D28: =C28+D13 | E28: =D28+E13 | F28: =E28+F13 | G28: =F28+G13 | H28: =G28+H13 | I28: =H28+I13 | J28: =I28+J13 | ... M28: =L28+M13 | N28: =M28 | O28: Investor 12M aktif (tidak ada churn di Tahun ke-1)
A29: Pengguna Aktif Pakar Pass 1-Bulan [A] | B29: =(B14+B19)+B22 | C29: =(C14+C19)+C22 | D29: =(D14+D19)+D22 | E29: =(E14+E19)+E22 | F29: =(F14+F19)+F22 | G29: =(G14+G19)+G22 | H29: =(H14+H19)+H22 | I29: =(I14+I19)+I22 | ... M29: =(M14+M19)+M22 | N29: =M29 | O29: Pakar 1M aktif (termasuk limpahan upgrade)
A30: Pengguna Aktif Pakar Pass 12-Bulan (Kumulatif 365 Hari) [A] | B30: =B15 | C30: =B30+C15 | D30: =C30+D15 | E30: =D30+E15 | F30: =E30+F15 | G30: =F30+G15 | H30: =G30+H15 | I30: =H30+I15 | J30: =I30+J15 | ... M30: =L30+M15 | N30: =M30 | O30: Pakar 12M aktif (tidak ada churn di Tahun ke-1)
A31: TOTAL PENGGUNA AKTIF BERBAYAR KAS [A] | B31: =SUM(B27:B30) | C31: =SUM(C27:C30) | D31: =SUM(D27:D30) | E31: =SUM(E27:E30) | F31: =SUM(F27:F30) | G31: =SUM(G27:G30) | H31: =SUM(H27:H30) | I31: =SUM(I27:I30) | ... M31: =SUM(M27:M30) | N31: =M31 | O31: Pengguna berbayar riil yang memiliki pass aktif
A32: Marketing Comp Accounts (Pakar Gratis) [S] | B32: =Model_Parameters!$B$23 | C32: =Model_Parameters!$B$23 | D32: =Model_Parameters!$B$23 | E32: =Model_Parameters!$B$23 | F32: =Model_Parameters!$B$23 | G32: =Model_Parameters!$B$23 | H32: =Model_Parameters!$B$23 | I32: =Model_Parameters!$B$23 | ... M32: =Model_Parameters!$B$23 | N32: =M32 | O32: 5 akun Pakar promosi gratis (Influencer/Komunitas)
A33: TOTAL AKUN AKTIF MENIKMATI AKSES [A] | B33: =B31+B32 | C33: =C31+C32 | D33: =D31+D32 | E33: =E31+E32 | F33: =F31+F32 | G33: =G31+G32 | H33: =H31+H32 | I33: =I31+I32 | ... M33: =M31+M32 | N33: =M33 | O33: Total akun aktif (Berbayar riil + 5 Akun Comp)
A34: Pemicu Migrasi VPS Fase 0 (<5 Paying Users) [S] | B34: =B31 | C34: =C31 | D34: =D31 | E34: =E31 | F34: =F31 | G34: =G31 | H34: =H31 | I34: =I31 | ... M34: =M31 | N34: =M34 | O34: AUDIT: Comp Accounts TIDAK DIHITUNG! Hanya kas > Rp 0
A35: V. PENERIMAAN KAS BRUTO (IDR) [S/A]
A36: Penerimaan Investor Pass 1-Bulan (Rp 19k) [S] | B36: =(B12+B18)*Model_Parameters!$B$7 | C36: =(C12+C18)*Model_Parameters!$B$7 | D36: =(D12+D18)*Model_Parameters!$B$7 | E36: =(E12+E18)*Model_Parameters!$B$7 | F36: =(F12+F18)*Model_Parameters!$B$7 | G36: =(G12+G18)*Model_Parameters!$B$7 | H36: =(H12+H18)*Model_Parameters!$B$7 | I36: =(I12+I18)*Model_Parameters!$B$7 | ... M36: =(M12+M18)*Model_Parameters!$B$7 | N36: =SUM(B36:M36) | O36: Penjualan baru + perpanjangan manual Investor 1M
A37: Penerimaan Investor Pass 12-Bulan (Rp 190k) [S] | B37: =B13*Model_Parameters!$B$8 | C37: =C13*Model_Parameters!$B$8 | D37: =D13*Model_Parameters!$B$8 | E37: =E13*Model_Parameters!$B$8 | F37: =F13*Model_Parameters!$B$8 | G37: =G13*Model_Parameters!$B$8 | H37: =H13*Model_Parameters!$B$8 | I37: =I13*Model_Parameters!$B$8 | ... M37: =M13*Model_Parameters!$B$8 | N37: =SUM(B37:M37) | O37: Penjualan Investor 12M di muka
A38: Penerimaan Pakar Pass 1-Bulan (Rp 49k) [S] | B38: =(B14+B19)*Model_Parameters!$B$9 | C38: =(C14+C19)*Model_Parameters!$B$9 | D38: =(D14+D19)*Model_Parameters!$B$9 | E38: =(E14+E19)*Model_Parameters!$B$9 | F38: =(F14+F19)*Model_Parameters!$B$9 | G38: =(G14+G19)*Model_Parameters!$B$9 | H38: =(H14+H19)*Model_Parameters!$B$9 | I38: =(I14+I19)*Model_Parameters!$B$9 | ... M38: =(M14+M19)*Model_Parameters!$B$9 | N38: =SUM(B38:M38) | O38: Penjualan baru + perpanjangan manual Pakar 1M
A39: Penerimaan Pakar Pass 12-Bulan (Rp 490k) [S] | B39: =B15*Model_Parameters!$B$10 | C39: =C15*Model_Parameters!$B$10 | D39: =D15*Model_Parameters!$B$10 | E39: =E15*Model_Parameters!$B$10 | F39: =F15*Model_Parameters!$B$10 | G39: =G15*Model_Parameters!$B$10 | H39: =H15*Model_Parameters!$B$10 | I39: =I15*Model_Parameters!$B$10 | ... M39: =M15*Model_Parameters!$B$10 | N39: =SUM(B39:M39) | O39: Penjualan Pakar 12M di muka
A40: Penerimaan Upgrade Tier Investor -> Pakar [A] | B40: =B25 | C40: =C25 | D40: =D25 | E40: =E25 | F40: =F25 | G40: =G25 | H40: =H25 | I40: =I25 | ... M40: =M25 | N40: =SUM(B40:M40) | O40: Kas masuk tambahan dari upgrade tier
A41: TOTAL PENERIMAAN KAS BRUTO [A] | B41: =SUM(B36:B40) | C41: =SUM(C36:C40) | D41: =SUM(D36:D40) | E41: =SUM(E36:E40) | F41: =SUM(F36:F40) | G41: =SUM(G36:G40) | H41: =SUM(H36:H40) | I41: =SUM(I36:I40) | ... M41: =SUM(M36:M40) | N41: =SUM(B41:M41) | O41: Total kas masuk kotor ke payment gateway
...

Sheet Skenario_Konservatif
A1: IHSG STORM — MODEL KEUANGAN 12 BULAN (SKENARIO 2: KONSERVATIF)
A2: Dinamika Bulanan: One-Time Pass, Perpanjangan Manual, Jalur Upgrade, Akun Comp, OpEx Phase 0 VPS (Drop Supabase) & Kas (v3.1) | Oscar
A4: Metrik / Pos Keuangan | B4: M1 (Nov) | C4: M2 (Des) | D4: M3 (Jan) | E4: M4 (Feb) | F4: M5 (Mar) | G4: M6 (Apr) | H4: M7 (Mei) | I4: M8 (Jun) | J4: M9 (Jul) | K4: M10 (Agu) | L4: M11 (Sep) | M4: M12 (Okt) | N4: Total 12 Bulan | O4: Keterangan & Formula
A5: I. TRAFIK & FUNNEL AKUISISI PENGGUNA
A6: Pengunjung Unik Bulanan [A] | B6: 1500 | C6: 2500 | D6: 4000 | E6: 6000 | F6: 8500 | G6: 11500 | H6: 14500 | I6: 17500 | J6: 20000 | K6: 22000 | L6: 23500 | M6: 25000 | N6: =SUM(B6:M6) | O6: Proyeksi trafik web unik bulanan
A7: Rasio Registrasi Akun Gratis (%) [A] | B7: 0.2 | C7: 0.2 | D7: 0.2 | E7: 0.2 | F7: 0.2 | G7: 0.2 | H7: 0.2 | I7: 0.2 | J7: 0.2 | K7: 0.2 | L7: 0.2 | M7: 0.2 | N7: =AVERAGE(B7:M7) | O7: Persentase pengunjung yang mendaftar gratis
A8: Pendaftaran Akun Gratis Baru (MoM) [A] | B8: =B6*B7 | C8: =C6*C7 | D8: =D6*D7 | E8: =E6*E7 | F8: =F6*F7 | G8: =G6*G7 | H8: =H6*H7 | I8: =I6*I7 | ... M8: =M6*M7 | N8: =SUM(B8:M8) | O8: Pengguna gratis baru per bulan
A9: Akumulasi Pengguna Gratis Terdaftar [A] | B9: =B8 | C9: =B9+C8 | D9: =C9+D8 | E9: =D9+E8 | F9: =E9+F8 | G9: =F9+G8 | H9: =G9+H8 | I9: =H9+I8 | J9: =I9+J8 | ... M9: =L9+M8 | N9: =M9 | O9: Total basis akun gratis kumulatif
A10: Tingkat Konversi Akun Baru ke Berbayar (%) [A] | B10: 0.015 | C10: 0.015 | D10: 0.015 | E10: 0.015 | F10: 0.015 | G10: 0.015 | H10: 0.015 | I10: 0.015 | J10: 0.015 | K10: 0.015 | L10: 0.015 | M10: 0.015 | N10: =AVERAGE(B10:M10) | O10: Persentase akun baru yang membeli pass berbayar
A11: Pelanggan Pembeli Pass Baru Total (Cohort) [A] | B11: =B8*B10 | C11: =C8*C10 | D11: =D8*D10 | E11: =E8*E10 | F11: =F8*F10 | G11: =G8*G10 | H11: =H8*H10 | I11: =I8*I10 | ... M11: =M8*M10 | N11: =SUM(B11:M11) | O11: Total pembeli baru pertama kali
A12: • Investor Pass 1-Bulan Baru (Rp 19k) [A] | B12: =B11*0.56 | C12: =C11*0.56 | D12: =D11*0.56 | E12: =E11*0.56 | F12: =F11*0.56 | G12: =G11*0.56 | H12: =H11*0.56 | I12: =I11*0.56 | ... M12: =M11*0.56 | N12: =SUM(B12:M12) | O12: 56% dari pembeli baru memilih Investor 1M
A13: • Investor Pass 12-Bulan Baru (Rp 190k) [A] | B13: =B11*0.14 | C13: =C11*0.14 | D13: =D11*0.14 | E13: =E11*0.14 | F13: =F11*0.14 | G13: =G11*0.14 | H13: =H11*0.14 | I13: =I11*0.14 | ... M13: =M11*0.14 | N13: =SUM(B13:M13) | O13: 14% dari pembeli baru memilih Investor 12M
A14: • Pakar Pass 1-Bulan Baru (Rp 49k) [A] | B14: =B11*0.24 | C14: =C11*0.24 | D14: =D11*0.24 | E14: =E11*0.24 | F14: =F11*0.24 | G14: =G11*0.24 | H14: =H11*0.24 | I14: =I11*0.24 | ... M14: =M11*0.24 | N14: =SUM(B14:M14) | O14: 24% dari pembeli baru memilih Pakar 1M
A15: • Pakar Pass 12-Bulan Baru (Rp 490k) [A] | B15: =B11*0.06 | C15: =C11*0.06 | D15: =D11*0.06 | E15: =E11*0.06 | F15: =F11*0.06 | G15: =G11*0.06 | H15: =H11*0.06 | I15: =I11*0.06 | ... M15: =M11*0.06 | N15: =SUM(B15:M15) | O15: 6% dari pembeli baru memilih Pakar 12M
A16: II. PEMBELIAN ULANG PASS 1-BULAN (REPEAT PURCHASE / MANUAL RENEWAL) [A]
A17: Tingkat Pembelian Ulang Manual (%) [A] | B17: 0.4 | C17: 0.4 | D17: 0.4 | E17: 0.4 | F17: 0.4 | G17: 0.4 | H17: 0.4 | I17: 0.4 | J17: 0.4 | K17: 0.4 | L17: 0.4 | M17: 0.4 | N17: =AVERAGE(B17:M17) | O17: Persentase pembeli 1M yang manual beli lagi saat habis
A18: Pembelian Ulang Investor Pass 1-Bulan [A] | B18: 0 | C18: =B27*C17 | D18: =C27*D17 | E18: =D27*E17 | F18: =E27*F17 | G18: =F27*G17 | H18: =G27*H17 | I18: =H27*I17 | J18: =I27*J17 | ... M18: =L27*M17 | N18: =SUM(B18:M18) | O18: Pembeli Investor 1M bulan lalu yang beli pass baru
A19: Pembelian Ulang Pakar Pass 1-Bulan [A] | B19: 0 | C19: =B29*C17 | D19: =C29*D17 | E19: =D29*E17 | F19: =E29*F17 | G19: =F29*G17 | H19: =G29*H17 | I19: =H29*I17 | J19: =I29*J17 | ... M19: =L29*M17 | N19: =SUM(B19:M19) | O19: Pembeli Pakar 1M bulan lalu yang beli pass baru
A20: III. JALUR UPGRADE TIER (INVESTOR -> PAKAR) [S/A]
A21: Tingkat Konversi Upgrade Investor ke Pakar (%) [A] | B21: 0.07 | C21: 0.07 | D21: 0.07 | E21: 0.07 | F21: 0.07 | G21: 0.07 | H21: 0.07 | I21: 0.07 | J21: 0.07 | K21: 0.07 | L21: 0.07 | M21: 0.07 | N21: =AVERAGE(B21:M21) | O21: Persentase pemegang Investor yang upgrade ke Pakar
A22: Jumlah Akun Investor 1M yang Upgrade [A] | B22: =(B12+B18)*B21 | C22: =(C12+C18)*C21 | D22: =(D12+D18)*D21 | E22: =(E12+E18)*E21 | F22: =(F12+F18)*F21 | G22: =(G12+G18)*G21 | H22: =(H12+H18)*H21 | I22: =(I12+I18)*I21 | ... M22: =(M12+M18)*M21 | N22: =SUM(B22:M22) | O22: Akun Investor 1M yang bayar selisih Rp 30k ke Pakar
A23: Pendapatan Kas Upgrade 1-Bulan (Rp 30k) [S] | B23: =B22*Model_Parameters!$B$16 | C23: =C22*Model_Parameters!$B$16 | D23: =D22*Model_Parameters!$B$16 | E23: =E22*Model_Parameters!$B$16 | F23: =F22*Model_Parameters!$B$16 | G23: =G22*Model_Parameters!$B$16 | H23: =H22*Model_Parameters!$B$16 | I23: =I22*Model_Parameters!$B$16 | ... M23: =M22*Model_Parameters!$B$16 | N23: =SUM(B23:M23) | O23: Kas masuk upgrade bulanan: Akun x Rp 30.000
A24: Pendapatan Kas Upgrade 12-Bulan (Prorata Rp 225k) [A] | B24: =(B13*(B21*0.5))*Model_Parameters!$B$17 | C24: =(C13*(C21*0.5))*Model_Parameters!$B$17 | D24: =(D13*(D21*0.5))*Model_Parameters!$B$17 | E24: =(E13*(E21*0.5))*Model_Parameters!$B$17 | F24: =(F13*(F21*0.5))*Model_Parameters!$B$17 | G24: =(G13*(G21*0.5))*Model_Parameters!$B$17 | H24: =(H13*(H21*0.5))*Model_Parameters!$B$17 | I24: =(I13*(I21*0.5))*Model_Parameters!$B$17 | ... M24: =(M13*(M21*0.5))*Model_Parameters!$B$17 | N24: =SUM(B24:M24) | O24: Kas masuk upgrade tahunan: Prorata sisa bulan
A25: TOTAL KAS MASUK DARI UPGRADE TIER [A] | B25: =B23+B24 | C25: =C23+C24 | D25: =D23+D24 | E25: =E23+E24 | F25: =F23+F24 | G25: =G23+G24 | H25: =H23+H24 | I25: =I23+I24 | ... M25: =M23+M24 | N25: =SUM(B25:M25) | O25: Total penerimaan kas dari seluruh transaksi upgrade
A26: IV. DINAMIKA PENGGUNA AKTIF BERBAYAR KAS & AKUN PROMOSI (COMP) [S/A]
A27: Pengguna Aktif Investor Pass 1-Bulan [A] | B27: =(B12+B18)-B22 | C27: =(C12+C18)-C22 | D27: =(D12+D18)-D22 | E27: =(E12+E18)-E22 | F27: =(F12+F18)-F22 | G27: =(G12+G18)-G22 | H27: =(H12+H18)-H22 | I27: =(I12+I18)-I22 | ... M27: =(M12+M18)-M22 | N27: =M27 | O27: Investor 1M aktif (dikurangi yang pindah ke Pakar)
A28: Pengguna Aktif Investor Pass 12-Bulan (Kumulatif 365 Hari) [A] | B28: =B13 | C28: =B28+C13 | D28: =C28+D13 | E28: =D28+E13 | F28: =E28+F13 | G28: =F28+G13 | H28: =G28+H13 | I28: =H28+I13 | J28: =I28+J13 | ... M28: =L28+M13 | N28: =M28 | O28: Investor 12M aktif (tidak ada churn di Tahun ke-1)
A29: Pengguna Aktif Pakar Pass 1-Bulan [A] | B29: =(B14+B19)+B22 | C29: =(C14+C19)+C22 | D29: =(D14+D19)+D22 | E29: =(E14+E19)+E22 | F29: =(F14+F19)+F22 | G29: =(G14+G19)+G22 | H29: =(H14+H19)+H22 | I29: =(I14+I19)+I22 | ... M29: =(M14+M19)+M22 | N29: =M29 | O29: Pakar 1M aktif (termasuk limpahan upgrade)
A30: Pengguna Aktif Pakar Pass 12-Bulan (Kumulatif 365 Hari) [A] | B30: =B15 | C30: =B30+C15 | D30: =C30+D15 | E30: =D30+E15 | F30: =E30+F15 | G30: =F30+G15 | H30: =G30+H15 | I30: =H30+I15 | J30: =I30+J15 | ... M30: =L30+M15 | N30: =M30 | O30: Pakar 12M aktif (tidak ada churn di Tahun ke-1)
A31: TOTAL PENGGUNA AKTIF BERBAYAR KAS [A] | B31: =SUM(B27:B30) | C31: =SUM(C27:C30) | D31: =SUM(D27:D30) | E31: =SUM(E27:E30) | F31: =SUM(F27:F30) | G31: =SUM(G27:G30) | H31: =SUM(H27:H30) | I31: =SUM(I27:I30) | ... M31: =SUM(M27:M30) | N31: =M31 | O31: Pengguna berbayar riil yang memiliki pass aktif
A32: Marketing Comp Accounts (Pakar Gratis) [S] | B32: =Model_Parameters!$B$23 | C32: =Model_Parameters!$B$23 | D32: =Model_Parameters!$B$23 | E32: =Model_Parameters!$B$23 | F32: =Model_Parameters!$B$23 | G32: =Model_Parameters!$B$23 | H32: =Model_Parameters!$B$23 | I32: =Model_Parameters!$B$23 | ... M32: =Model_Parameters!$B$23 | N32: =M32 | O32: 5 akun Pakar promosi gratis (Influencer/Komunitas)
A33: TOTAL AKUN AKTIF MENIKMATI AKSES [A] | B33: =B31+B32 | C33: =C31+C32 | D33: =D31+D32 | E33: =E31+E32 | F33: =F31+F32 | G33: =G31+G32 | H33: =H31+H32 | I33: =I31+I32 | ... M33: =M31+M32 | N33: =M33 | O33: Total akun aktif (Berbayar riil + 5 Akun Comp)
A34: Pemicu Migrasi VPS Fase 0 (<5 Paying Users) [S] | B34: =B31 | C34: =C31 | D34: =D31 | E34: =E31 | F34: =F31 | G34: =G31 | H34: =H31 | I34: =I31 | ... M34: =M31 | N34: =M34 | O34: AUDIT: Comp Accounts TIDAK DIHITUNG! Hanya kas > Rp 0
A35: V. PENERIMAAN KAS BRUTO (IDR) [S/A]
A36: Penerimaan Investor Pass 1-Bulan (Rp 19k) [S] | B36: =(B12+B18)*Model_Parameters!$B$7 | C36: =(C12+C18)*Model_Parameters!$B$7 | D36: =(D12+D18)*Model_Parameters!$B$7 | E36: =(E12+E18)*Model_Parameters!$B$7 | F36: =(F12+F18)*Model_Parameters!$B$7 | G36: =(G12+G18)*Model_Parameters!$B$7 | H36: =(H12+H18)*Model_Parameters!$B$7 | I36: =(I12+I18)*Model_Parameters!$B$7 | ... M36: =(M12+M18)*Model_Parameters!$B$7 | N36: =SUM(B36:M36) | O36: Penjualan baru + perpanjangan manual Investor 1M
A37: Penerimaan Investor Pass 12-Bulan (Rp 190k) [S] | B37: =B13*Model_Parameters!$B$8 | C37: =C13*Model_Parameters!$B$8 | D37: =D13*Model_Parameters!$B$8 | E37: =E13*Model_Parameters!$B$8 | F37: =F13*Model_Parameters!$B$8 | G37: =G13*Model_Parameters!$B$8 | H37: =H13*Model_Parameters!$B$8 | I37: =I13*Model_Parameters!$B$8 | ... M37: =M13*Model_Parameters!$B$8 | N37: =SUM(B37:M37) | O37: Penjualan Investor 12M di muka
A38: Penerimaan Pakar Pass 1-Bulan (Rp 49k) [S] | B38: =(B14+B19)*Model_Parameters!$B$9 | C38: =(C14+C19)*Model_Parameters!$B$9 | D38: =(D14+D19)*Model_Parameters!$B$9 | E38: =(E14+E19)*Model_Parameters!$B$9 | F38: =(F14+F19)*Model_Parameters!$B$9 | G38: =(G14+G19)*Model_Parameters!$B$9 | H38: =(H14+H19)*Model_Parameters!$B$9 | I38: =(I14+I19)*Model_Parameters!$B$9 | ... M38: =(M14+M19)*Model_Parameters!$B$9 | N38: =SUM(B38:M38) | O38: Penjualan baru + perpanjangan manual Pakar 1M
A39: Penerimaan Pakar Pass 12-Bulan (Rp 490k) [S] | B39: =B15*Model_Parameters!$B$10 | C39: =C15*Model_Parameters!$B$10 | D39: =D15*Model_Parameters!$B$10 | E39: =E15*Model_Parameters!$B$10 | F39: =F15*Model_Parameters!$B$10 | G39: =G15*Model_Parameters!$B$10 | H39: =H15*Model_Parameters!$B$10 | I39: =I15*Model_Parameters!$B$10 | ... M39: =M15*Model_Parameters!$B$10 | N39: =SUM(B39:M39) | O39: Penjualan Pakar 12M di muka
A40: Penerimaan Upgrade Tier Investor -> Pakar [A] | B40: =B25 | C40: =C25 | D40: =D25 | E40: =E25 | F40: =F25 | G40: =G25 | H40: =H25 | I40: =I25 | ... M40: =M25 | N40: =SUM(B40:M40) | O40: Kas masuk tambahan dari upgrade tier
A41: TOTAL PENERIMAAN KAS BRUTO [A] | B41: =SUM(B36:B40) | C41: =SUM(C36:C40) | D41: =SUM(D36:D40) | E41: =SUM(E36:E40) | F41: =SUM(F36:F40) | G41: =SUM(G36:G40) | H41: =SUM(H36:H40) | I41: =SUM(I36:I40) | ... M41: =SUM(M36:M40) | N41: =SUM(B41:M41) | O41: Total kas masuk kotor ke payment gateway
...

Sheet Skenario_Moderat_Base
A1: IHSG STORM — MODEL KEUANGAN 12 BULAN (SKENARIO 3: MODERAT (BASE CASE))
A2: Dinamika Bulanan: One-Time Pass, Perpanjangan Manual, Jalur Upgrade, Akun Comp, OpEx Phase 0 VPS (Drop Supabase) & Kas (v3.1) | Oscar
A4: Metrik / Pos Keuangan | B4: M1 (Nov) | C4: M2 (Des) | D4: M3 (Jan) | E4: M4 (Feb) | F4: M5 (Mar) | G4: M6 (Apr) | H4: M7 (Mei) | I4: M8 (Jun) | J4: M9 (Jul) | K4: M10 (Agu) | L4: M11 (Sep) | M4: M12 (Okt) | N4: Total 12 Bulan | O4: Keterangan & Formula
A5: I. TRAFIK & FUNNEL AKUISISI PENGGUNA
A6: Pengunjung Unik Bulanan [A] | B6: 3500 | C6: 6000 | D6: 9500 | E6: 14000 | F6: 19500 | G6: 26000 | H6: 32500 | I6: 38500 | J6: 44000 | K6: 48500 | L6: 52000 | M6: 55000 | N6: =SUM(B6:M6) | O6: Proyeksi trafik web unik bulanan
A7: Rasio Registrasi Akun Gratis (%) [A] | B7: 0.25 | C7: 0.25 | D7: 0.25 | E7: 0.25 | F7: 0.25 | G7: 0.25 | H7: 0.25 | I7: 0.25 | J7: 0.25 | K7: 0.25 | L7: 0.25 | M7: 0.25 | N7: =AVERAGE(B7:M7) | O7: Persentase pengunjung yang mendaftar gratis
A8: Pendaftaran Akun Gratis Baru (MoM) [A] | B8: =B6*B7 | C8: =C6*C7 | D8: =D6*D7 | E8: =E6*E7 | F8: =F6*F7 | G8: =G6*G7 | H8: =H6*H7 | I8: =I6*I7 | ... M8: =M6*M7 | N8: =SUM(B8:M8) | O8: Pengguna gratis baru per bulan
A9: Akumulasi Pengguna Gratis Terdaftar [A] | B9: =B8 | C9: =B9+C8 | D9: =C9+D8 | E9: =D9+E8 | F9: =E9+F8 | G9: =F9+G8 | H9: =G9+H8 | I9: =H9+I8 | J9: =I9+J8 | ... M9: =L9+M8 | N9: =M9 | O9: Total basis akun gratis kumulatif
A10: Tingkat Konversi Akun Baru ke Berbayar (%) [A] | B10: 0.0135 | C10: 0.0135 | D10: 0.0135 | E10: 0.0135 | F10: 0.0135 | G10: 0.0135 | H10: 0.0135 | I10: 0.0135 | J10: 0.0135 | K10: 0.0135 | L10: 0.0135 | M10: 0.0135 | N10: =AVERAGE(B10:M10) | O10: Persentase akun baru yang membeli pass berbayar
A11: Pelanggan Pembeli Pass Baru Total (Cohort) [A] | B11: =B8*B10 | C11: =C8*C10 | D11: =D8*D10 | E11: =E8*E10 | F11: =F8*F10 | G11: =G8*G10 | H11: =H8*H10 | I11: =I8*I10 | ... M11: =M8*M10 | N11: =SUM(B11:M11) | O11: Total pembeli baru pertama kali
A12: • Investor Pass 1-Bulan Baru (Rp 19k) [A] | B12: =B11*0.56 | C12: =C11*0.56 | D12: =D11*0.56 | E12: =E11*0.56 | F12: =F11*0.56 | G12: =G11*0.56 | H12: =H11*0.56 | I12: =I11*0.56 | ... M12: =M11*0.56 | N12: =SUM(B12:M12) | O12: 56% dari pembeli baru memilih Investor 1M
A13: • Investor Pass 12-Bulan Baru (Rp 190k) [A] | B13: =B11*0.14 | C13: =C11*0.14 | D13: =D11*0.14 | E13: =E11*0.14 | F13: =F11*0.14 | G13: =G11*0.14 | H13: =H11*0.14 | I13: =I11*0.14 | ... M13: =M11*0.14 | N13: =SUM(B13:M13) | O13: 14% dari pembeli baru memilih Investor 12M
A14: • Pakar Pass 1-Bulan Baru (Rp 49k) [A] | B14: =B11*0.24 | C14: =C11*0.24 | D14: =D11*0.24 | E14: =E11*0.24 | F14: =F11*0.24 | G14: =G11*0.24 | H14: =H11*0.24 | I14: =I11*0.24 | ... M14: =M11*0.24 | N14: =SUM(B14:M14) | O14: 24% dari pembeli baru memilih Pakar 1M
A15: • Pakar Pass 12-Bulan Baru (Rp 490k) [A] | B15: =B11*0.06 | C15: =C11*0.06 | D15: =D11*0.06 | E15: =E11*0.06 | F15: =F11*0.06 | G15: =G11*0.06 | H15: =H11*0.06 | I15: =I11*0.06 | ... M15: =M11*0.06 | N15: =SUM(B15:M15) | O15: 6% dari pembeli baru memilih Pakar 12M
A16: II. PEMBELIAN ULANG PASS 1-BULAN (REPEAT PURCHASE / MANUAL RENEWAL) [A]
A17: Tingkat Pembelian Ulang Manual (%) [A] | B17: 0.45 | C17: 0.45 | D17: 0.45 | E17: 0.45 | F17: 0.45 | G17: 0.45 | H17: 0.45 | I17: 0.45 | J17: 0.45 | K17: 0.45 | L17: 0.45 | M17: 0.45 | N17: =AVERAGE(B17:M17) | O17: Persentase pembeli 1M yang manual beli lagi saat habis
A18: Pembelian Ulang Investor Pass 1-Bulan [A] | B18: 0 | C18: =B27*C17 | D18: =C27*D17 | E18: =D27*E17 | F18: =E27*F17 | G18: =F27*G17 | H18: =G27*H17 | I18: =H27*I17 | J18: =I27*J17 | ... M18: =L27*M17 | N18: =SUM(B18:M18) | O18: Pembeli Investor 1M bulan lalu yang beli pass baru
A19: Pembelian Ulang Pakar Pass 1-Bulan [A] | B19: 0 | C19: =B29*C17 | D19: =C29*D17 | E19: =D29*E17 | F19: =E29*F17 | G19: =F29*G17 | H19: =G29*H17 | I19: =H29*I17 | J19: =I29*J17 | ... M19: =L29*M17 | N19: =SUM(B19:M19) | O19: Pembeli Pakar 1M bulan lalu yang beli pass baru
A20: III. JALUR UPGRADE TIER (INVESTOR -> PAKAR) [S/A]
A21: Tingkat Konversi Upgrade Investor ke Pakar (%) [A] | B21: 0.08 | C21: 0.08 | D21: 0.08 | E21: 0.08 | F21: 0.08 | G21: 0.08 | H21: 0.08 | I21: 0.08 | J21: 0.08 | K21: 0.08 | L21: 0.08 | M21: 0.08 | N21: =AVERAGE(B21:M21) | O21: Persentase pemegang Investor yang upgrade ke Pakar
A22: Jumlah Akun Investor 1M yang Upgrade [A] | B22: =(B12+B18)*B21 | C22: =(C12+C18)*C21 | D22: =(D12+D18)*D21 | E22: =(E12+E18)*E21 | F22: =(F12+F18)*F21 | G22: =(G12+G18)*G21 | H22: =(H12+H18)*H21 | I22: =(I12+I18)*I21 | ... M22: =(M12+M18)*M21 | N22: =SUM(B22:M22) | O22: Akun Investor 1M yang bayar selisih Rp 30k ke Pakar
A23: Pendapatan Kas Upgrade 1-Bulan (Rp 30k) [S] | B23: =B22*Model_Parameters!$B$16 | C23: =C22*Model_Parameters!$B$16 | D23: =D22*Model_Parameters!$B$16 | E23: =E22*Model_Parameters!$B$16 | F23: =F22*Model_Parameters!$B$16 | G23: =G22*Model_Parameters!$B$16 | H23: =H22*Model_Parameters!$B$16 | I23: =I22*Model_Parameters!$B$16 | ... M23: =M22*Model_Parameters!$B$16 | N23: =SUM(B23:M23) | O23: Kas masuk upgrade bulanan: Akun x Rp 30.000
A24: Pendapatan Kas Upgrade 12-Bulan (Prorata Rp 225k) [A] | B24: =(B13*(B21*0.5))*Model_Parameters!$B$17 | C24: =(C13*(C21*0.5))*Model_Parameters!$B$17 | D24: =(D13*(D21*0.5))*Model_Parameters!$B$17 | E24: =(E13*(E21*0.5))*Model_Parameters!$B$17 | F24: =(F13*(F21*0.5))*Model_Parameters!$B$17 | G24: =(G13*(G21*0.5))*Model_Parameters!$B$17 | H24: =(H13*(H21*0.5))*Model_Parameters!$B$17 | I24: =(I13*(I21*0.5))*Model_Parameters!$B$17 | ... M24: =(M13*(M21*0.5))*Model_Parameters!$B$17 | N24: =SUM(B24:M24) | O24: Kas masuk upgrade tahunan: Prorata sisa bulan
A25: TOTAL KAS MASUK DARI UPGRADE TIER [A] | B25: =B23+B24 | C25: =C23+C24 | D25: =D23+D24 | E25: =E23+E24 | F25: =F23+F24 | G25: =G23+G24 | H25: =H23+H24 | I25: =I23+I24 | ... M25: =M23+M24 | N25: =SUM(B25:M25) | O25: Total penerimaan kas dari seluruh transaksi upgrade
A26: IV. DINAMIKA PENGGUNA AKTIF BERBAYAR KAS & AKUN PROMOSI (COMP) [S/A]
A27: Pengguna Aktif Investor Pass 1-Bulan [A] | B27: =(B12+B18)-B22 | C27: =(C12+C18)-C22 | D27: =(D12+D18)-D22 | E27: =(E12+E18)-E22 | F27: =(F12+F18)-F22 | G27: =(G12+G18)-G22 | H27: =(H12+H18)-H22 | I27: =(I12+I18)-I22 | ... M27: =(M12+M18)-M22 | N27: =M27 | O27: Investor 1M aktif (dikurangi yang pindah ke Pakar)
A28: Pengguna Aktif Investor Pass 12-Bulan (Kumulatif 365 Hari) [A] | B28: =B13 | C28: =B28+C13 | D28: =C28+D13 | E28: =D28+E13 | F28: =E28+F13 | G28: =F28+G13 | H28: =G28+H13 | I28: =H28+I13 | J28: =I28+J13 | ... M28: =L28+M13 | N28: =M28 | O28: Investor 12M aktif (tidak ada churn di Tahun ke-1)
A29: Pengguna Aktif Pakar Pass 1-Bulan [A] | B29: =(B14+B19)+B22 | C29: =(C14+C19)+C22 | D29: =(D14+D19)+D22 | E29: =(E14+E19)+E22 | F29: =(F14+F19)+F22 | G29: =(G14+G19)+G22 | H29: =(H14+H19)+H22 | I29: =(I14+I19)+I22 | ... M29: =(M14+M19)+M22 | N29: =M29 | O29: Pakar 1M aktif (termasuk limpahan upgrade)
A30: Pengguna Aktif Pakar Pass 12-Bulan (Kumulatif 365 Hari) [A] | B30: =B15 | C30: =B30+C15 | D30: =C30+D15 | E30: =D30+E15 | F30: =E30+F15 | G30: =F30+G15 | H30: =G30+H15 | I30: =H30+I15 | J30: =I30+J15 | ... M30: =L30+M15 | N30: =M30 | O30: Pakar 12M aktif (tidak ada churn di Tahun ke-1)
A31: TOTAL PENGGUNA AKTIF BERBAYAR KAS [A] | B31: =SUM(B27:B30) | C31: =SUM(C27:C30) | D31: =SUM(D27:D30) | E31: =SUM(E27:E30) | F31: =SUM(F27:F30) | G31: =SUM(G27:G30) | H31: =SUM(H27:H30) | I31: =SUM(I27:I30) | ... M31: =SUM(M27:M30) | N31: =M31 | O31: Pengguna berbayar riil yang memiliki pass aktif
A32: Marketing Comp Accounts (Pakar Gratis) [S] | B32: =Model_Parameters!$B$23 | C32: =Model_Parameters!$B$23 | D32: =Model_Parameters!$B$23 | E32: =Model_Parameters!$B$23 | F32: =Model_Parameters!$B$23 | G32: =Model_Parameters!$B$23 | H32: =Model_Parameters!$B$23 | I32: =Model_Parameters!$B$23 | ... M32: =Model_Parameters!$B$23 | N32: =M32 | O32: 5 akun Pakar promosi gratis (Influencer/Komunitas)
A33: TOTAL AKUN AKTIF MENIKMATI AKSES [A] | B33: =B31+B32 | C33: =C31+C32 | D33: =D31+D32 | E33: =E31+E32 | F33: =F31+F32 | G33: =G31+G32 | H33: =H31+H32 | I33: =I31+I32 | ... M33: =M31+M32 | N33: =M33 | O33: Total akun aktif (Berbayar riil + 5 Akun Comp)
A34: Pemicu Migrasi VPS Fase 0 (<5 Paying Users) [S] | B34: =B31 | C34: =C31 | D34: =D31 | E34: =E31 | F34: =F31 | G34: =G31 | H34: =H31 | I34: =I31 | ... M34: =M31 | N34: =M34 | O34: AUDIT: Comp Accounts TIDAK DIHITUNG! Hanya kas > Rp 0
A35: V. PENERIMAAN KAS BRUTO (IDR) [S/A]
A36: Penerimaan Investor Pass 1-Bulan (Rp 19k) [S] | B36: =(B12+B18)*Model_Parameters!$B$7 | C36: =(C12+C18)*Model_Parameters!$B$7 | D36: =(D12+D18)*Model_Parameters!$B$7 | E36: =(E12+E18)*Model_Parameters!$B$7 | F36: =(F12+F18)*Model_Parameters!$B$7 | G36: =(G12+G18)*Model_Parameters!$B$7 | H36: =(H12+H18)*Model_Parameters!$B$7 | I36: =(I12+I18)*Model_Parameters!$B$7 | ... M36: =(M12+M18)*Model_Parameters!$B$7 | N36: =SUM(B36:M36) | O36: Penjualan baru + perpanjangan manual Investor 1M
A37: Penerimaan Investor Pass 12-Bulan (Rp 190k) [S] | B37: =B13*Model_Parameters!$B$8 | C37: =C13*Model_Parameters!$B$8 | D37: =D13*Model_Parameters!$B$8 | E37: =E13*Model_Parameters!$B$8 | F37: =F13*Model_Parameters!$B$8 | G37: =G13*Model_Parameters!$B$8 | H37: =H13*Model_Parameters!$B$8 | I37: =I13*Model_Parameters!$B$8 | ... M37: =M13*Model_Parameters!$B$8 | N37: =SUM(B37:M37) | O37: Penjualan Investor 12M di muka
A38: Penerimaan Pakar Pass 1-Bulan (Rp 49k) [S] | B38: =(B14+B19)*Model_Parameters!$B$9 | C38: =(C14+C19)*Model_Parameters!$B$9 | D38: =(D14+D19)*Model_Parameters!$B$9 | E38: =(E14+E19)*Model_Parameters!$B$9 | F38: =(F14+F19)*Model_Parameters!$B$9 | G38: =(G14+G19)*Model_Parameters!$B$9 | H38: =(H14+H19)*Model_Parameters!$B$9 | I38: =(I14+I19)*Model_Parameters!$B$9 | ... M38: =(M14+M19)*Model_Parameters!$B$9 | N38: =SUM(B38:M38) | O38: Penjualan baru + perpanjangan manual Pakar 1M
A39: Penerimaan Pakar Pass 12-Bulan (Rp 490k) [S] | B39: =B15*Model_Parameters!$B$10 | C39: =C15*Model_Parameters!$B$10 | D39: =D15*Model_Parameters!$B$10 | E39: =E15*Model_Parameters!$B$10 | F39: =F15*Model_Parameters!$B$10 | G39: =G15*Model_Parameters!$B$10 | H39: =H15*Model_Parameters!$B$10 | I39: =I15*Model_Parameters!$B$10 | ... M39: =M15*Model_Parameters!$B$10 | N39: =SUM(B39:M39) | O39: Penjualan Pakar 12M di muka
A40: Penerimaan Upgrade Tier Investor -> Pakar [A] | B40: =B25 | C40: =C25 | D40: =D25 | E40: =E25 | F40: =F25 | G40: =G25 | H40: =H25 | I40: =I25 | ... M40: =M25 | N40: =SUM(B40:M40) | O40: Kas masuk tambahan dari upgrade tier
A41: TOTAL PENERIMAAN KAS BRUTO [A] | B41: =SUM(B36:B40) | C41: =SUM(C36:C40) | D41: =SUM(D36:D40) | E41: =SUM(E36:E40) | F41: =SUM(F36:F40) | G41: =SUM(G36:G40) | H41: =SUM(H36:H40) | I41: =SUM(I36:I40) | ... M41: =SUM(M36:M40) | N41: =SUM(B41:M41) | O41: Total kas masuk kotor ke payment gateway
...

Sheet Skenario_Optimis
A1: IHSG STORM — MODEL KEUANGAN 12 BULAN (SKENARIO 4: OPTIMIS)
A2: Dinamika Bulanan: One-Time Pass, Perpanjangan Manual, Jalur Upgrade, Akun Comp, OpEx Phase 0 VPS (Drop Supabase) & Kas (v3.1) | Oscar
A4: Metrik / Pos Keuangan | B4: M1 (Nov) | C4: M2 (Des) | D4: M3 (Jan) | E4: M4 (Feb) | F4: M5 (Mar) | G4: M6 (Apr) | H4: M7 (Mei) | I4: M8 (Jun) | J4: M9 (Jul) | K4: M10 (Agu) | L4: M11 (Sep) | M4: M12 (Okt) | N4: Total 12 Bulan | O4: Keterangan & Formula
A5: I. TRAFIK & FUNNEL AKUISISI PENGGUNA
A6: Pengunjung Unik Bulanan [A] | B6: 6000 | C6: 12000 | D6: 20000 | E6: 31000 | F6: 45000 | G6: 61000 | H6: 77000 | I6: 92000 | J6: 105000 | K6: 115000 | L6: 123000 | M6: 130000 | N6: =SUM(B6:M6) | O6: Proyeksi trafik web unik bulanan
A7: Rasio Registrasi Akun Gratis (%) [A] | B7: 0.3 | C7: 0.3 | D7: 0.3 | E7: 0.3 | F7: 0.3 | G7: 0.3 | H7: 0.3 | I7: 0.3 | J7: 0.3 | K7: 0.3 | L7: 0.3 | M7: 0.3 | N7: =AVERAGE(B7:M7) | O7: Persentase pengunjung yang mendaftar gratis
A8: Pendaftaran Akun Gratis Baru (MoM) [A] | B8: =B6*B7 | C8: =C6*C7 | D8: =D6*D7 | E8: =E6*E7 | F8: =F6*F7 | G8: =G6*G7 | H8: =H6*H7 | I8: =I6*I7 | ... M8: =M6*M7 | N8: =SUM(B8:M8) | O8: Pengguna gratis baru per bulan
A9: Akumulasi Pengguna Gratis Terdaftar [A] | B9: =B8 | C9: =B9+C8 | D9: =C9+D8 | E9: =D9+E8 | F9: =E9+F8 | G9: =F9+G8 | H9: =G9+H8 | I9: =H9+I8 | J9: =I9+J8 | ... M9: =L9+M8 | N9: =M9 | O9: Total basis akun gratis kumulatif
A10: Tingkat Konversi Akun Baru ke Berbayar (%) [A] | B10: 0.025 | C10: 0.025 | D10: 0.025 | E10: 0.025 | F10: 0.025 | G10: 0.025 | H10: 0.025 | I10: 0.025 | J10: 0.025 | K10: 0.025 | L10: 0.025 | M10: 0.025 | N10: =AVERAGE(B10:M10) | O10: Persentase akun baru yang membeli pass berbayar
A11: Pelanggan Pembeli Pass Baru Total (Cohort) [A] | B11: =B8*B10 | C11: =C8*C10 | D11: =D8*D10 | E11: =E8*E10 | F11: =F8*F10 | G11: =G8*G10 | H11: =H8*H10 | I11: =I8*I10 | ... M11: =M8*M10 | N11: =SUM(B11:M11) | O11: Total pembeli baru pertama kali
A12: • Investor Pass 1-Bulan Baru (Rp 19k) [A] | B12: =B11*0.56 | C12: =C11*0.56 | D12: =D11*0.56 | E12: =E11*0.56 | F12: =F11*0.56 | G12: =G11*0.56 | H12: =H11*0.56 | I12: =I11*0.56 | ... M12: =M11*0.56 | N12: =SUM(B12:M12) | O12: 56% dari pembeli baru memilih Investor 1M
A13: • Investor Pass 12-Bulan Baru (Rp 190k) [A] | B13: =B11*0.14 | C13: =C11*0.14 | D13: =D11*0.14 | E13: =E11*0.14 | F13: =F11*0.14 | G13: =G11*0.14 | H13: =H11*0.14 | I13: =I11*0.14 | ... M13: =M11*0.14 | N13: =SUM(B13:M13) | O13: 14% dari pembeli baru memilih Investor 12M
A14: • Pakar Pass 1-Bulan Baru (Rp 49k) [A] | B14: =B11*0.24 | C14: =C11*0.24 | D14: =D11*0.24 | E14: =E11*0.24 | F14: =F11*0.24 | G14: =G11*0.24 | H14: =H11*0.24 | I14: =I11*0.24 | ... M14: =M11*0.24 | N14: =SUM(B14:M14) | O14: 24% dari pembeli baru memilih Pakar 1M
A15: • Pakar Pass 12-Bulan Baru (Rp 490k) [A] | B15: =B11*0.06 | C15: =C11*0.06 | D15: =D11*0.06 | E15: =E11*0.06 | F15: =F11*0.06 | G15: =G11*0.06 | H15: =H11*0.06 | I15: =I11*0.06 | ... M15: =M11*0.06 | N15: =SUM(B15:M15) | O15: 6% dari pembeli baru memilih Pakar 12M
A16: II. PEMBELIAN ULANG PASS 1-BULAN (REPEAT PURCHASE / MANUAL RENEWAL) [A]
A17: Tingkat Pembelian Ulang Manual (%) [A] | B17: 0.55 | C17: 0.55 | D17: 0.55 | E17: 0.55 | F17: 0.55 | G17: 0.55 | H17: 0.55 | I17: 0.55 | J17: 0.55 | K17: 0.55 | L17: 0.55 | M17: 0.55 | N17: =AVERAGE(B17:M17) | O17: Persentase pembeli 1M yang manual beli lagi saat habis
A18: Pembelian Ulang Investor Pass 1-Bulan [A] | B18: 0 | C18: =B27*C17 | D18: =C27*D17 | E18: =D27*E17 | F18: =E27*F17 | G18: =F27*G17 | H18: =G27*H17 | I18: =H27*I17 | J18: =I27*J17 | ... M18: =L27*M17 | N18: =SUM(B18:M18) | O18: Pembeli Investor 1M bulan lalu yang beli pass baru
A19: Pembelian Ulang Pakar Pass 1-Bulan [A] | B19: 0 | C19: =B29*C17 | D19: =C29*D17 | E19: =D29*E17 | F19: =E29*F17 | G19: =F29*G17 | H19: =G29*H17 | I19: =H29*I17 | J19: =I29*J17 | ... M19: =L29*M17 | N19: =SUM(B19:M19) | O19: Pembeli Pakar 1M bulan lalu yang beli pass baru
A20: III. JALUR UPGRADE TIER (INVESTOR -> PAKAR) [S/A]
A21: Tingkat Konversi Upgrade Investor ke Pakar (%) [A] | B21: 0.1 | C21: 0.1 | D21: 0.1 | E21: 0.1 | F21: 0.1 | G21: 0.1 | H21: 0.1 | I21: 0.1 | J21: 0.1 | K21: 0.1 | L21: 0.1 | M21: 0.1 | N21: =AVERAGE(B21:M21) | O21: Persentase pemegang Investor yang upgrade ke Pakar
A22: Jumlah Akun Investor 1M yang Upgrade [A] | B22: =(B12+B18)*B21 | C22: =(C12+C18)*C21 | D22: =(D12+D18)*D21 | E22: =(E12+E18)*E21 | F22: =(F12+F18)*F21 | G22: =(G12+G18)*G21 | H22: =(H12+H18)*H21 | I22: =(I12+I18)*I21 | ... M22: =(M12+M18)*M21 | N22: =SUM(B22:M22) | O22: Akun Investor 1M yang bayar selisih Rp 30k ke Pakar
A23: Pendapatan Kas Upgrade 1-Bulan (Rp 30k) [S] | B23: =B22*Model_Parameters!$B$16 | C23: =C22*Model_Parameters!$B$16 | D23: =D22*Model_Parameters!$B$16 | E23: =E22*Model_Parameters!$B$16 | F23: =F22*Model_Parameters!$B$16 | G23: =G22*Model_Parameters!$B$16 | H23: =H22*Model_Parameters!$B$16 | I23: =I22*Model_Parameters!$B$16 | ... M23: =M22*Model_Parameters!$B$16 | N23: =SUM(B23:M23) | O23: Kas masuk upgrade bulanan: Akun x Rp 30.000
A24: Pendapatan Kas Upgrade 12-Bulan (Prorata Rp 225k) [A] | B24: =(B13*(B21*0.5))*Model_Parameters!$B$17 | C24: =(C13*(C21*0.5))*Model_Parameters!$B$17 | D24: =(D13*(D21*0.5))*Model_Parameters!$B$17 | E24: =(E13*(E21*0.5))*Model_Parameters!$B$17 | F24: =(F13*(F21*0.5))*Model_Parameters!$B$17 | G24: =(G13*(G21*0.5))*Model_Parameters!$B$17 | H24: =(H13*(H21*0.5))*Model_Parameters!$B$17 | I24: =(I13*(I21*0.5))*Model_Parameters!$B$17 | ... M24: =(M13*(M21*0.5))*Model_Parameters!$B$17 | N24: =SUM(B24:M24) | O24: Kas masuk upgrade tahunan: Prorata sisa bulan
A25: TOTAL KAS MASUK DARI UPGRADE TIER [A] | B25: =B23+B24 | C25: =C23+C24 | D25: =D23+D24 | E25: =E23+E24 | F25: =F23+F24 | G25: =G23+G24 | H25: =H23+H24 | I25: =I23+I24 | ... M25: =M23+M24 | N25: =SUM(B25:M25) | O25: Total penerimaan kas dari seluruh transaksi upgrade
A26: IV. DINAMIKA PENGGUNA AKTIF BERBAYAR KAS & AKUN PROMOSI (COMP) [S/A]
A27: Pengguna Aktif Investor Pass 1-Bulan [A] | B27: =(B12+B18)-B22 | C27: =(C12+C18)-C22 | D27: =(D12+D18)-D22 | E27: =(E12+E18)-E22 | F27: =(F12+F18)-F22 | G27: =(G12+G18)-G22 | H27: =(H12+H18)-H22 | I27: =(I12+I18)-I22 | ... M27: =(M12+M18)-M22 | N27: =M27 | O27: Investor 1M aktif (dikurangi yang pindah ke Pakar)
A28: Pengguna Aktif Investor Pass 12-Bulan (Kumulatif 365 Hari) [A] | B28: =B13 | C28: =B28+C13 | D28: =C28+D13 | E28: =D28+E13 | F28: =E28+F13 | G28: =F28+G13 | H28: =G28+H13 | I28: =H28+I13 | J28: =I28+J13 | ... M28: =L28+M13 | N28: =M28 | O28: Investor 12M aktif (tidak ada churn di Tahun ke-1)
A29: Pengguna Aktif Pakar Pass 1-Bulan [A] | B29: =(B14+B19)+B22 | C29: =(C14+C19)+C22 | D29: =(D14+D19)+D22 | E29: =(E14+E19)+E22 | F29: =(F14+F19)+F22 | G29: =(G14+G19)+G22 | H29: =(H14+H19)+H22 | I29: =(I14+I19)+I22 | ... M29: =(M14+M19)+M22 | N29: =M29 | O29: Pakar 1M aktif (termasuk limpahan upgrade)
A30: Pengguna Aktif Pakar Pass 12-Bulan (Kumulatif 365 Hari) [A] | B30: =B15 | C30: =B30+C15 | D30: =C30+D15 | E30: =D30+E15 | F30: =E30+F15 | G30: =F30+G15 | H30: =G30+H15 | I30: =H30+I15 | J30: =I30+J15 | ... M30: =L30+M15 | N30: =M30 | O30: Pakar 12M aktif (tidak ada churn di Tahun ke-1)
A31: TOTAL PENGGUNA AKTIF BERBAYAR KAS [A] | B31: =SUM(B27:B30) | C31: =SUM(C27:C30) | D31: =SUM(D27:D30) | E31: =SUM(E27:E30) | F31: =SUM(F27:F30) | G31: =SUM(G27:G30) | H31: =SUM(H27:H30) | I31: =SUM(I27:I30) | ... M31: =SUM(M27:M30) | N31: =M31 | O31: Pengguna berbayar riil yang memiliki pass aktif
A32: Marketing Comp Accounts (Pakar Gratis) [S] | B32: =Model_Parameters!$B$23 | C32: =Model_Parameters!$B$23 | D32: =Model_Parameters!$B$23 | E32: =Model_Parameters!$B$23 | F32: =Model_Parameters!$B$23 | G32: =Model_Parameters!$B$23 | H32: =Model_Parameters!$B$23 | I32: =Model_Parameters!$B$23 | ... M32: =Model_Parameters!$B$23 | N32: =M32 | O32: 5 akun Pakar promosi gratis (Influencer/Komunitas)
A33: TOTAL AKUN AKTIF MENIKMATI AKSES [A] | B33: =B31+B32 | C33: =C31+C32 | D33: =D31+D32 | E33: =E31+E32 | F33: =F31+F32 | G33: =G31+G32 | H33: =H31+H32 | I33: =I31+I32 | ... M33: =M31+M32 | N33: =M33 | O33: Total akun aktif (Berbayar riil + 5 Akun Comp)
A34: Pemicu Migrasi VPS Fase 0 (<5 Paying Users) [S] | B34: =B31 | C34: =C31 | D34: =D31 | E34: =E31 | F34: =F31 | G34: =G31 | H34: =H31 | I34: =I31 | ... M34: =M31 | N34: =M34 | O34: AUDIT: Comp Accounts TIDAK DIHITUNG! Hanya kas > Rp 0
A35: V. PENERIMAAN KAS BRUTO (IDR) [S/A]
A36: Penerimaan Investor Pass 1-Bulan (Rp 19k) [S] | B36: =(B12+B18)*Model_Parameters!$B$7 | C36: =(C12+C18)*Model_Parameters!$B$7 | D36: =(D12+D18)*Model_Parameters!$B$7 | E36: =(E12+E18)*Model_Parameters!$B$7 | F36: =(F12+F18)*Model_Parameters!$B$7 | G36: =(G12+G18)*Model_Parameters!$B$7 | H36: =(H12+H18)*Model_Parameters!$B$7 | I36: =(I12+I18)*Model_Parameters!$B$7 | ... M36: =(M12+M18)*Model_Parameters!$B$7 | N36: =SUM(B36:M36) | O36: Penjualan baru + perpanjangan manual Investor 1M
A37: Penerimaan Investor Pass 12-Bulan (Rp 190k) [S] | B37: =B13*Model_Parameters!$B$8 | C37: =C13*Model_Parameters!$B$8 | D37: =D13*Model_Parameters!$B$8 | E37: =E13*Model_Parameters!$B$8 | F37: =F13*Model_Parameters!$B$8 | G37: =G13*Model_Parameters!$B$8 | H37: =H13*Model_Parameters!$B$8 | I37: =I13*Model_Parameters!$B$8 | ... M37: =M13*Model_Parameters!$B$8 | N37: =SUM(B37:M37) | O37: Penjualan Investor 12M di muka
A38: Penerimaan Pakar Pass 1-Bulan (Rp 49k) [S] | B38: =(B14+B19)*Model_Parameters!$B$9 | C38: =(C14+C19)*Model_Parameters!$B$9 | D38: =(D14+D19)*Model_Parameters!$B$9 | E38: =(E14+E19)*Model_Parameters!$B$9 | F38: =(F14+F19)*Model_Parameters!$B$9 | G38: =(G14+G19)*Model_Parameters!$B$9 | H38: =(H14+H19)*Model_Parameters!$B$9 | I38: =(I14+I19)*Model_Parameters!$B$9 | ... M38: =(M14+M19)*Model_Parameters!$B$9 | N38: =SUM(B38:M38) | O38: Penjualan baru + perpanjangan manual Pakar 1M
A39: Penerimaan Pakar Pass 12-Bulan (Rp 490k) [S] | B39: =B15*Model_Parameters!$B$10 | C39: =C15*Model_Parameters!$B$10 | D39: =D15*Model_Parameters!$B$10 | E39: =E15*Model_Parameters!$B$10 | F39: =F15*Model_Parameters!$B$10 | G39: =G15*Model_Parameters!$B$10 | H39: =H15*Model_Parameters!$B$10 | I39: =I15*Model_Parameters!$B$10 | ... M39: =M15*Model_Parameters!$B$10 | N39: =SUM(B39:M39) | O39: Penjualan Pakar 12M di muka
A40: Penerimaan Upgrade Tier Investor -> Pakar [A] | B40: =B25 | C40: =C25 | D40: =D25 | E40: =E25 | F40: =F25 | G40: =G25 | H40: =H25 | I40: =I25 | ... M40: =M25 | N40: =SUM(B40:M40) | O40: Kas masuk tambahan dari upgrade tier
A41: TOTAL PENERIMAAN KAS BRUTO [A] | B41: =SUM(B36:B40) | C41: =SUM(C36:C40) | D41: =SUM(D36:D40) | E41: =SUM(E36:E40) | F41: =SUM(F36:F40) | G41: =SUM(G36:G40) | H41: =SUM(H36:H40) | I41: =SUM(I36:I40) | ... M41: =SUM(M36:M40) | N41: =SUM(B41:M41) | O41: Total kas masuk kotor ke payment gateway
...

Sheet OneTime_vs_Recurring
A1: IHSG STORM — ANALISIS KOMPARASI SATU KALI BAYAR VS BERULANG (THE ACQUISITION TREADMILL)
A2: Dampak Penghapusan Auto-Debit, Kebutuhan Pembeli Baru Bulanan, Kehilangan ARR & Kurva Kas | Oscar
A4: 1. ANALISIS TREADMILL AKUISISI: JUMLAH PEMBELI BARU YANG DIBUTUHKAN SETIAP BULAN UNTUK MENUTUP BEBAN [S/A]
A5: Fase Tangga Biaya | B5: Ambang Batas Pengguna | C5: OpEx Tetap Bulanan [S] | D5: Investor 1M (Nett Rp 18,3k) | E5: Pakar 1M (Nett Rp 47,7k) | F5: Blended Mix 70/30 (Nett Rp 27,1k) | G5: Kebutuhan di Model Recurring (Auto-Renew Churn 6,5%) | H5: Evaluasi Beban Treadmill Akuisisi
A6: Fase 0 (VPS Phase 0 + AI Claude) | B6: < 5 Pelanggan Berbayar | C6: 390000 | D6: =ROUNDUP(C6/18306, 0) | E6: =ROUNDUP(C6/47724, 0) | F6: =ROUNDUP(C6/27131, 0) | G6: 2 | H6: Wajib dapat 15 pembeli baru/bln di One-Time vs 2 di Recurring
A7: Fase 1 (Vercel Pro + AI Claude) | B7: 5 - 49 Pelanggan | C7: 710000 | D7: =ROUNDUP(C7/18306, 0) | E7: =ROUNDUP(C7/47724, 0) | F7: =ROUNDUP(C7/27131, 0) | G7: 3 | H7: Wajib dapat 27 pembeli baru/bln di One-Time vs 3 di Recurring
A8: Fase 2 (Vercel + AI + EODHD $20) | B8: 50 - 499 Pelanggan (M4+) | C8: 1030000 | D8: =ROUNDUP(C8/18306, 0) | E8: =ROUNDUP(C8/47724, 0) | F8: =ROUNDUP(C8/27131, 0) | G8: 4 | H8: Wajib dapat 38 pembeli baru/bln di One-Time vs 4 di Recurring
